<mujoco model="GTPR">
    <compiler angle="radian" />
    <size njmax="500" nconmax="100" />
    <asset>
		<!-- bázis -->
        <mesh name="base_link" file="base_link.STL" />
		<!-- felkar -->
        <mesh name="A1" file="A1.STL" />
		<!-- felső középrész -->
        <mesh name="U1" file="U1.STL" />
		<!-- bal alkar -->
        <mesh name="U1L" file="U1L.STL" />
		<!-- bal alkarhoz tartozó alsórész -->
        <mesh name="L1-L" file="L1-L.STL" />
		<!-- bal alkarhoz tartozó munkaháromszög -->
        <mesh name="WL1-1" file="WL1-1.STL" />
		<!-- jobb alkar -->
        <mesh name="U1R" file="U1R.STL" />
		<!-- jobb alkarhoz tartozó alsórész -->
        <mesh name="L1-R" file="L1-R.STL" />
		<!-- jobb alkarhoz tartozó munkaháromszög -->
        <mesh name="WL1-2" file="WL1-2.STL" />
		
		<!-- felkar -->
        <mesh name="A2" file="A2.STL" />
		<!-- felső középrész -->
        <mesh name="U2" file="U2.STL" />
		<!-- bal alkar -->
        <mesh name="U2L" file="U2L.STL" />
		<!-- bal alkarhoz tartozó alsórész -->
        <mesh name="L2-L" file="L2-L.STL" />
		<!-- bal alkarhoz tartozó munkaháromszög -->
        <mesh name="WL2-1" file="WL2-1.STL" />
		<!-- jobb alkar -->
        <mesh name="U2R" file="U2R.STL" />
		<!-- jobb alkarhoz tartozó alsórész -->
        <mesh name="L2-R" file="L2-R.STL" />
		<!-- jobb alkarhoz tartozó munkaháromszög -->
        <mesh name="WL2-2" file="WL2-2.STL" />
		
		<!-- felkar -->
        <mesh name="A3" file="A3.STL" />
		<!-- felső középrész -->
        <mesh name="U3" file="U3.STL" />
		<!-- bal alkar -->
        <mesh name="U3L" file="U3L.STL" />
		<!-- bal alkarhoz tartozó alsórész -->
		<mesh name="L3-R" file="L3-R.STL" />
		<!-- bal alkarhoz tartozó munkaháromszög -->
        <mesh name="WL3-L" file="WL3-L.STL" />
		<!-- munkaháromszög -->
        <mesh name="WL3-1" file="WL3-1.STL" />
        <mesh name="U3R" file="U3R.STL" />
		<!-- jobb alkarhoz tartozó munkaháromszög ??? -->
        <mesh name="WL3-R" file="WL3-R.STL" />
		<!-- munkaháromszög -->
        <mesh name="WL3-2" file="WL3-2.STL" />
		
    </asset>
	<equality>
		<connect anchor="0.57735 0.57735 0.57735" active="true" body1="L1-R" body2="L1-L" ></connect>
		<connect anchor="0.57735 0.57735 0.57735" active="true" body1="L1-L" body2="L1-R" ></connect>
		
		<connect anchor="0.57735 0.57735 0.57735" active="true" body1="L2-R" body2="L2-L" ></connect>
		<connect anchor="0.57735 0.57735 0.57735" active="true" body1="L2-L" body2="L2-R" ></connect>
		
		<connect anchor="0.57735 0.57735 0.57735" active="true" body1="L3-R" body2="WL3-L" ></connect>
		<connect anchor="0.57735 0.57735 0.57735" active="true" body1="WL3-L" body2="L3-R" ></connect>
		
		
		<connect anchor="0 0 0" active="true" body1="U1L" body2="L1-R" ></connect>
		<connect anchor="0 0 0" active="true" body1="U1L" body2="L1-L" ></connect>
		<connect anchor="0 0 0" active="true" body1="U1R" body2="L1-L" ></connect>
		<connect anchor="0 0 0" active="true" body1="U1R" body2="L1-R" ></connect>
		
		<connect anchor="0 0 0" active="true" body1="U2L" body2="L2-R" ></connect>
		<connect anchor="0 0 0" active="true" body1="U2L" body2="L2-L" ></connect>
		<connect anchor="0 0 0" active="true" body1="U2R" body2="L2-L" ></connect>
		<connect anchor="0 0 0" active="true" body1="U2R" body2="L2-R" ></connect>
		
		<connect anchor="0 0 0" active="true" body1="U3L" body2="L3-R" ></connect>
		<connect anchor="0 0 0" active="true" body1="U3L" body2="WL3-L" ></connect>
		<connect anchor="0 0 0" active="true" body1="U3R" body2="WL3-L" ></connect>
		<connect anchor="0 0 0" active="true" body1="U3R" body2="L3-R" ></connect>
		
		<connect anchor="0.57735 0.57735 0.57735" active="true" body1="L1-R" body2="L2-L" ></connect>
		<connect anchor="0.57735 0.57735 0.57735" active="true" body1="L1-R" body2="L2-R" ></connect>
		<connect anchor="0.57735 0.57735 0.57735" active="true" body1="L1-L" body2="L3-R" ></connect>
		<connect anchor="0.57735 0.57735 0.57735" active="true" body1="L1-L" body2="L2-L" ></connect>
		<connect anchor="0.57735 0.57735 0.57735" active="true" body1="L2-R" body2="WL3-L" ></connect>
		<connect anchor="0.57735 0.57735 0.57735" active="true" body1="L2-R" body2="L3-R" ></connect>
		<connect anchor="0.57735 0.57735 0.57735" active="true" body1="L2-L" body2="L1-R" ></connect>
		<connect anchor="0.57735 0.57735 0.57735" active="true" body1="L2-L" body2="WL3-L" ></connect>
		<connect anchor="0.57735 0.57735 0.57735" active="true" body1="L3-R" body2="L2-L" ></connect>
		<connect anchor="0.57735 0.57735 0.57735" active="true" body1="L3-R" body2="L1-R" ></connect>
		<connect anchor="0.57735 0.57735 0.57735" active="true" body1="WL3-L" body2="L2-R" ></connect>
		<connect anchor="0.57735 0.57735 0.57735" active="true" body1="WL3-L" body2="L1-L" ></connect>
		
		
		<!-- <connect anchor="0.57735 0.57735 0.57735" active="true" body1="base_link" body2="A1" solimp="0.02 0.1 0.05" solref="0.06 1"></connect> -->
		<!-- <connect anchor="0.57735 0.57735 0.57735" active="true" body1="A1" body2="U1" solimp="0.02 0.1 0.05" solref="0.06 1"></connect> -->
		<!-- <connect anchor="0.57735 0.57735 0.57735" active="true" body1="U1" body2="U1L" solimp="0.02 0.1 0.05" solref="0.06 1"></connect> -->
		<!-- <connect anchor="0.57735 0.57735 0.57735" active="true" body1="U1" body2="U1R" solimp="0.02 0.1 0.05" solref="0.06 1"></connect> -->
		<!-- <connect anchor="0.57735 0.57735 0.57735" active="true" body1="U1R" body2="L1-R" solimp="0.02 0.1 0.05" solref="0.06 1"></connect> -->
		<!-- <connect anchor="0.57735 0.57735 0.57735" active="true" body1="U1L" body2="L1-R" solimp="0.02 0.1 0.05" solref="0.06 1"></connect> -->
		
		
		
		<!-- <connect anchor="0.57735 0.57735 0.57735" active="true" body1="U1L" body2="L1-L" solimp="0.02 0.1 0.05" solref="0.06 1"></connect> -->
		<!-- <connect anchor="0.57735 0.57735 0.57735" active="true" body1="L1-L" body2="WL1-1" solimp="0.02 0.1 0.05" solref="0.06 1"></connect> -->
		<!-- <connect anchor="0.57735 0.57735 0.57735" active="true" body1="U1R" body2="L1-R" solimp="0.02 0.1 0.05" solref="0.06 1"></connect> -->
		<!-- <connect anchor="0.57735 0.57735 0.57735" active="true" body1="L1-R" body2="WL1-2" solimp="0.02 0.1 0.05" solref="0.06 1"></connect> -->

		<!-- <connect anchor="0.57735 0.57735 0.57735" active="true" body1="base_link" body2="A2" solimp="0.02 0.1 0.05" solref="0.06 1"></connect> -->
		<!-- <connect anchor="0.57735 0.57735 0.57735" active="true" body1="A2" body2="U2" solimp="0.02 0.1 0.05" solref="0.06 1"></connect> -->
		<!-- <connect anchor="0.57735 0.57735 0.57735" active="true" body1="U2" body2="U2L" solimp="0.02 0.1 0.05" solref="0.06 1"></connect> -->
		<!-- <connect anchor="0.57735 0.57735 0.57735" active="true" body1="U2" body2="U2R" solimp="0.02 0.1 0.05" solref="0.06 1"></connect> -->
		<!-- <connect anchor="0.57735 0.57735 0.57735" active="true" body1="U2L" body2="L2-L" solimp="0.02 0.1 0.05" solref="0.06 1"></connect> -->
		<!-- <connect anchor="0.57735 0.57735 0.57735" active="true" body1="L2-L" body2="WL2-1" solimp="0.02 0.1 0.05" solref="0.06 1"></connect> -->
		<!-- <connect anchor="0.57735 0.57735 0.57735" active="true" body1="U2R" body2="L2-R" solimp="0.02 0.1 0.05" solref="0.06 1"></connect> -->
		<!-- <connect anchor="0.57735 0.57735 0.57735" active="true" body1="L2-R" body2="WL2-2" solimp="0.02 0.1 0.05" solref="0.06 1"></connect> -->
		
		<!-- <connect anchor="0.57735 0.57735 0.57735" active="true" body1="base_link" body2="A3" solimp="0.02 0.1 0.05" solref="0.06 1"></connect> -->
		<!-- <connect anchor="0.57735 0.57735 0.57735" active="true" body1="A3" body2="U3" solimp="0.02 0.1 0.05" solref="0.06 1"></connect> -->
		<!-- <connect anchor="0.57735 0.57735 0.57735" active="true" body1="U3" body2="U3L" solimp="0.02 0.1 0.05" solref="0.06 1"></connect> -->
		<!-- <connect anchor="0.57735 0.57735 0.57735" active="true" body1="U3" body2="U3R" solimp="0.02 0.1 0.05" solref="0.06 1"></connect> -->
		<!-- <connect anchor="0.57735 0.57735 0.57735" active="true" body1="U3L" body2="WL3-L" solimp="0.02 0.1 0.05" solref="0.06 1"></connect> -->
		<!-- <connect anchor="0.57735 0.57735 0.57735" active="true" body1="WL3-L" body2="WL3-1" solimp="0.02 0.1 0.05" solref="0.06 1"></connect> -->
		<!-- <connect anchor="0.57735 0.57735 0.57735" active="true" body1="U3R" body2="WL3-R" solimp="0.02 0.1 0.05" solref="0.06 1"></connect> -->
		<!-- <connect anchor="0.57735 0.57735 0.57735" active="true" body1="WL3-R" body2="WL3-2" solimp="0.02 0.1 0.05" solref="0.06 1"></connect> -->
		
		
		<!-- <connect anchor="0.57735 0.57735 0.57735" active="true" body1="base_link" body2="A1" solimp="0.02 0.1 0.05" solref="0.06 1"></connect> -->
		<!-- <connect anchor="0.57735 0.57735 0.57735" active="true" body1="A1" body2="U1" solimp="0.02 0.1 0.05" solref="0.06 1"></connect> -->
		<!-- <connect anchor="0.57735 0.57735 0.57735" active="true" body1="U1" body2="U1L" solimp="0.02 0.1 0.05" solref="0.06 1"></connect> -->
		<!-- <connect anchor="0.57735 0.57735 0.57735" active="true" body1="U1L" body2="L1-L" solimp="0.02 0.1 0.05" solref="0.06 1"></connect> -->
		<!-- <connect anchor="0.57735 0.57735 0.57735" active="true" body1="L1-L" body2="WL1-1" solimp="0.02 0.1 0.05" solref="0.06 1"></connect> -->
		<!-- <connect anchor="0.57735 0.57735 0.57735" active="true" body1="U1" body2="U1R" solimp="0.02 0.1 0.05" solref="0.06 1"></connect> -->
		<!-- <connect anchor="0.57735 0.57735 0.57735" active="true" body1="U1R" body2="L1-R" solimp="0.02 0.1 0.05" solref="0.06 1"></connect> -->
		<!-- <connect anchor="0.57735 0.57735 0.57735" active="true" body1="L1-R" body2="WL1-2" solimp="0.02 0.1 0.05" solref="0.06 1"></connect> -->
		<!-- <connect anchor="0.57735 0.57735 0.57735" active="true" body1="base_link" body2="A2" solimp="0.02 0.1 0.05" solref="0.06 1"></connect> -->
		<!-- <connect anchor="0.57735 0.57735 0.57735" active="true" body1="A2" body2="U2" solimp="0.02 0.1 0.05" solref="0.06 1"></connect> -->
		<!-- <connect anchor="0.57735 0.57735 0.57735" active="true" body1="U2" body2="U2L" solimp="0.02 0.1 0.05" solref="0.06 1"></connect> -->
		<!-- <connect anchor="0.57735 0.57735 0.57735" active="true" body1="U2L" body2="L2-L" solimp="0.02 0.1 0.05" solref="0.06 1"></connect> -->
		<!-- <connect anchor="0.57735 0.57735 0.57735" active="true" body1="L2-L" body2="WL2-1" solimp="0.02 0.1 0.05" solref="0.06 1"></connect> -->
		<!-- <connect anchor="0.57735 0.57735 0.57735" active="true" body1="U2" body2="U2R" solimp="0.02 0.1 0.05" solref="0.06 1"></connect> -->
		<!-- <connect anchor="0.57735 0.57735 0.57735" active="true" body1="U2R" body2="L2-R" solimp="0.02 0.1 0.05" solref="0.06 1"></connect> -->
		<!-- <connect anchor="0.57735 0.57735 0.57735" active="true" body1="L2-R" body2="WL2-2" solimp="0.02 0.1 0.05" solref="0.06 1"></connect> -->
		<!-- <connect anchor="0.57735 0.57735 0.57735" active="true" body1="base_link" body2="A3" solimp="0.02 0.1 0.05" solref="0.06 1"></connect> -->
		<!-- <connect anchor="0.57735 0.57735 0.57735" active="true" body1="A3" body2="U3" solimp="0.02 0.1 0.05" solref="0.06 1"></connect> -->
		<!-- <connect anchor="0.57735 0.57735 0.57735" active="true" body1="U3" body2="U3L" solimp="0.02 0.1 0.05" solref="0.06 1"></connect> -->
		<!-- <connect anchor="0.57735 0.57735 0.57735" active="true" body1="U3L" body2="WL3-L" solimp="0.02 0.1 0.05" solref="0.06 1"></connect> -->
		<!-- <connect anchor="0.57735 0.57735 0.57735" active="true" body1="WL3-L" body2="WL3-1" solimp="0.02 0.1 0.05" solref="0.06 1"></connect> -->
		<!-- <connect anchor="0.57735 0.57735 0.57735" active="true" body1="U3" body2="U3R" solimp="0.02 0.1 0.05" solref="0.06 1"></connect> -->
		<!-- <connect anchor="0.57735 0.57735 0.57735" active="true" body1="U3R" body2="WL3-R" solimp="0.02 0.1 0.05" solref="0.06 1"></connect> -->
		<!-- <connect anchor="0.57735 0.57735 0.57735" active="true" body1="WL3-R" body2="WL3-2" solimp="0.02 0.1 0.05" solref="0.06 1"></connect> -->
		
	</equality>
    <worldbody>
	<body name="base_link" pos="-2.3525E-17 -0.005 2.3559E-17" >
        <geom type="mesh" rgba="0.7451 0.7451 0.7451 1" mesh="base_link" />
        <body name="A1" pos="0 0.2 -0.15" quat="0.707105 0.707108 0 0">
            <inertial pos="5.3777e-05 4.4185e-09 0.1" mass="0.015311" diaginertia="4.8682e-05 4.8682e-05 1.9135e-07" />
			
            <joint name="A1" pos="0 0 0.2" axis="-40 0 0" type="hinge" range="-2.2854 1.714602" damping="1.0"/>
            <geom type="mesh" rgba="0.7451 0.7451 0.7451 1" mesh="A1" />
            <body name="U1" pos="-0.05 0 0" quat="0.435887 0.556777 0.435891 0.556777">
                <inertial pos="-0.000110499 -1.29114e-08 0.05" mass="0.00745719" diaginertia="5.6949e-06 5.69478e-06 9.31377e-08" />
                <joint name="U1" pos="0 0 0.05" axis="0.57735 0.57735 0.57735" type="ball"/>
                
                <geom type="mesh" rgba="0.745098 0.745098 0.745098 1" mesh="U1" />
                <body name="U1L" pos="0 -0.5 0" quat="-2.59734e-06 -2.59735e-06 0.707108 0.707105">
                    <inertial pos="-2.12633e-05 -2.09104e-08 0.25" mass="0.0388723" diaginertia="0.000794044 0.000794044 4.85892e-07" />
					<joint name="U1_2" pos="0 0 0.5" axis="0.57735 0.57735 0.57735" type="hinge" range="-2.2854 1.714602" damping="1.0"/>
					
                    <geom type="mesh" rgba="0.745098 0.745098 0.745098 1" mesh="U1L" />
                    <body name="L1-L" pos="0 0 0" quat="-2.59734e-06 -2.59735e-06 -0.707108 -0.707105">
                        <inertial pos="-0.0001105 -1.2911e-08 0.05" mass="0.0074572" diaginertia="5.6949e-06 5.6948e-06 9.3138e-08" />
                        <joint name="L1-L" pos="0 0 0.1" axis="0.57735 0.57735 0.57735" type="ball"/>
						<!-- ez is valami balalsó gömbcsukló -->
                        <geom type="mesh" rgba="0.7451 0.7451 0.7451 1" mesh="L1-L" />
                        <!-- <body name="WL1-1" pos="0.029123 -0.0072 0.05" quat="0.556782 0.435881 -0.556784 0.435882"> -->
                            <!-- <inertial pos="0 0 0.005" quat="0.5 0.5 -0.5 0.5" mass="0.010825" diaginertia="2.1494e-06 1.1649e-06 1.1649e-06" /> -->
                            <!-- <joint name="WL1-1" pos="0 0 0" axis="0.57735 0.57735 0.57735" /> -->
                            <!-- <geom type="mesh" rgba="0.7451 0.7451 0.7451 1" mesh="WL1-1" /> -->
                        <!-- </body> -->
                    </body>
                </body>
                <body name="U1R" pos="0 -0.5 0.1" quat="-2.59734e-06 -2.59735e-06 0.707108 0.707105">
                    <inertial pos="-2.12633e-05 -2.09104e-08 0.25" mass="0.0388723" diaginertia="0.000794044 0.000794044 4.85892e-07" />
					<joint name="U1_3" pos="0 0 0.5" axis="0.57735 0.57735 0.57735" type="ball"/>
                    <!-- <joint name="U1R" pos="0 0 0" axis="0.57735 0.57735 0.57735" type="ball"/>  !!!!!!!!!!!!!! -->
                    <geom type="mesh" rgba="0.745098 0.745098 0.745098 1" mesh="U1R" />
                    <body name="L1-R" pos="0 -0.1 0" quat="-2.59734e-06 -2.59735e-06 -0.707108 -0.707105">
                        <inertial pos="-0.000110499 -1.29114e-08 0.05" mass="0.00745719" diaginertia="5.6949e-06 5.69478e-06 9.31377e-08" />
                        <joint name="L1-R" pos="0 0 0" axis="0.57735 0.57735 0.57735" type="ball"/>
                        <geom type="mesh" rgba="0.745098 0.745098 0.745098 1" mesh="L1-R" />
                        <!-- <body name="WL1-2" pos="0.029123 -0.0072 0.05" quat="0.556782 0.435881 -0.556784 0.435882"> -->
                            <!-- <inertial pos="0 0 0.005" quat="0.5 0.5 -0.5 0.5" mass="0.0108253" diaginertia="2.14943e-06 1.16492e-06 1.16492e-06" /> -->
                            <!-- <joint name="WL1-2" pos="0 0 0" axis="0.57735 0.57735 0.57735" /> -->
                            <!-- <geom type="mesh" rgba="0.745098 0.745098 0.745098 1" mesh="WL1-2" /> -->
                        <!-- </body> -->
                    </body>
                </body>
            </body>
        </body>
       <body name="A2" pos="-0.1299 0.2 0.075" quat="0.353553 0.353556 0.612372 -0.612372">
            <inertial pos="5.37741e-05 3.61649e-09 0.1" mass="0.0153111" diaginertia="4.86817e-05 4.86816e-05 1.91354e-07" />
            <joint name="A2" pos="0 0 0.2" axis="-40 0 0" type="hinge" range="-2.2854 1.714602" damping="1.0"/>
            <geom type="mesh" rgba="0.745098 0.745098 0.745098 1" mesh="A2" />
            <body name="U2" pos="-0.05 0 0" quat="0.435887 0.556777 0.435891 0.556777">
                <inertial pos="-0.000110517 -3.26421e-08 0.05" mass="0.00745716" diaginertia="5.6949e-06 5.69477e-06 9.31377e-08" />
                <joint name="U2" pos="0 0 0.05" axis="0.57735 0.57735 0.57735" type="hinge" range="-2.2854 1.714602" damping="1.0"/>
                <geom type="mesh" rgba="0.745098 0.745098 0.745098 1" mesh="U2" />
                <body name="U2L" pos="0 -0.5 0" quat="-2.59734e-06 -2.59735e-06 0.707108 0.707105">
                    <inertial pos="-2.1272e-05 -3.14319e-08 0.25" mass="0.0388723" diaginertia="0.000794044 0.000794044 4.85892e-07" />
                    <joint name="U2L" pos="0 0 0.5" axis="0.57735 0.57735 0.57735" type="ball" />
                    <geom type="mesh" rgba="0.745098 0.745098 0.745098 1" mesh="U2L" />
                    <body name="L2-L" pos="-0.0016491 0.10098 -0.0004077" quat="-2.59734e-06 2.59735e-06 -0.707108 0.707105">
                        <inertial pos="-0.0017596 -0.000407723 0.0509808" mass="0.00745716" diaginertia="5.6949e-06 5.69477e-06 9.31377e-08" />
                        <joint name="L2-L" pos="0 0 0" axis="0.57735 0.57735 0.57735" type="ball"/>
                        <geom type="mesh" rgba="0.745098 0.745098 0.745098 1" mesh="L2-L" />
                        <!-- <body name="WL2-1" pos="0.027474 0.0067923 0.050981" quat="0.655878 0.700129 -0.099102 0.26424"> -->
                            <!-- <inertial pos="0 0 0.005" quat="0.5 0.5 -0.5 0.5" mass="0.0108253" diaginertia="2.14943e-06 1.16492e-06 1.16492e-06" /> -->
                            <!-- <joint name="WL2-1" pos="0 0 0" axis="0.57735 0.57735 0.57735" /> -->
                            <!-- <geom type="mesh" rgba="0.745098 0.745098 0.745098 1" mesh="WL2-1" /> -->
                        <!-- </body> -->
                    </body>
                </body>
                <body name="U2R" pos="0 -0.5 0.1" quat="-2.59734e-06 -2.59735e-06 0.707108 0.707105">
                    <inertial pos="-2.1272e-05 -3.14319e-08 0.25" mass="0.0388723" diaginertia="0.000794044 0.000794044 4.85892e-07" />
                    <joint name="U2R" pos="0 0 0.5" axis="0.57735 0.57735 0.57735" type="ball"/>
                    <geom type="mesh" rgba="0.745098 0.745098 0.745098 1" mesh="U2R" />
                    <body name="L2-R" pos="0 0 0" quat="-2.59734e-06 2.59735e-06 0.707108 -0.707105"> 
                        <inertial pos="-0.000110519 -2.80939e-08 0.05" mass="0.00745716" diaginertia="5.6949e-06 5.69477e-06 9.31377e-08" />
                        <joint name="L2-R" pos="0 0 0.1" axis="0.57735 0.57735 0.57735" type="ball"/>
                        <geom type="mesh" rgba="0.745098 0.745098 0.745098 1" mesh="L2-R" />
                        <!-- <body name="WL2-2" pos="0.029123 0.0072 0.05" quat="0.655878 0.700129 -0.099102 0.26424"> -->
                            <!-- <inertial pos="0 0 0.005" quat="0.5 0.5 -0.5 0.5" mass="0.0108253" diaginertia="2.14943e-06 1.16492e-06 1.16492e-06" /> -->
                            <!-- <joint name="WL2-2" pos="0 0 0" axis="0.57735 0.57735 0.57735" /> -->
                            <!-- <geom type="mesh" rgba="0.745098 0.745098 0.745098 1" mesh="WL2-2" /> -->
                        <!-- </body> -->
                    </body>
                </body>
            </body>
        </body>
        <body name="A3" pos="0.1299 0.2 0.075" quat="0.353553 0.353556 -0.612372 0.612372">
            <inertial pos="5.37741e-05 5.17042e-09 0.1" mass="0.0153111" diaginertia="4.86817e-05 4.86816e-05 1.91354e-07" />
            <joint name="A3" pos="0 0 0.2" axis="-40 0 0" type="hinge" range="-2.2854 1.714602" damping="1.0"/>
            <geom type="mesh" rgba="0.745098 0.745098 0.745098 1" mesh="A3" />
            <body name="U3" pos="0.05 0 0" quat="0.435887 0.556777 -0.435891 -0.556777">
                <inertial pos="-0.000110519 -2.80939e-08 0.05" mass="0.00745716" diaginertia="5.6949e-06 5.69477e-06 9.31377e-08" />
                <joint name="U3" pos="0 0 0.05" axis="0.57735 0.57735 0.57735" type="hinge" range="-2.2854 1.714602" damping="1.0"/>
                <geom type="mesh" rgba="0.745098 0.745098 0.745098 1" mesh="U3" />
                <body name="U3L" pos="-0.0016491 -0.50041 0.10098" quat="-2.59734e-06 -2.59735e-06 0.707108 0.707105">
                    <inertial pos="-0.00167036 -0.000980784 0.250408" mass="0.0388723" diaginertia="0.000794043 0.000794043 4.85892e-07" />
                    <joint name="U3L" pos="0 0 0.5" axis="0.57735 0.57735 0.57735" type="ball"/>
                    <geom type="mesh" rgba="0.745098 0.745098 0.745098 1" mesh="U3L" />
                    <body name="WL3-L" pos="0 -0.10196 0" quat="-2.59734e-06 -2.59735e-06 0.707108 0.707105">
                        <inertial pos="0.00153856 0.000407667 0.0509808" mass="0.00745716" diaginertia="5.6949e-06 5.69477e-06 9.31377e-08" />
                        <joint name="WL3-L" pos="0 0 0" axis="0.57735 0.57735 0.57735" type="ball"/>
                        <geom type="mesh" rgba="0.745098 0.745098 0.745098 1" mesh="WL3-L" />
                        <!-- <body name="WL3-1" pos="-0.027474 -0.0067923 0.050981" quat="0.700126 -0.655881 -0.264239 -0.099103"> -->
                            <!-- <inertial pos="0 0 0.005" quat="0.5 0.5 -0.5 0.5" mass="0.0108253" diaginertia="2.14943e-06 1.16492e-06 1.16492e-06" /> -->
                            <!-- <joint name="WL3-1" pos="0 0 0" axis="0.57735 0.57735 0.57735" /> -->
                            <!-- <geom type="mesh" rgba="0.745098 0.745098 0.745098 1" mesh="WL3-1" /> -->
                        <!-- </body> -->
                    </body>
                </body>
                <body name="U3R" pos="0 -0.5 0" quat="-2.59734e-06 -2.59735e-06 0.707108 0.707105"> 
                    <inertial pos="-2.12759e-05 -2.22829e-08 0.25" mass="0.0388723" diaginertia="0.000794043 0.000794043 4.85892e-07" />
                    <joint name="U3R" pos="0 0 0.5" axis="0.57735 0.57735 0.57735" type="ball"/>
                    <geom type="mesh" rgba="0.745098 0.745098 0.745098 1" mesh="U3R" />
                    <body name="L3-R" pos="0 0 0" quat="-2.59734e-06 -2.59735e-06 0.707108 0.707105">
                        <inertial pos="-0.000110519 -2.80939e-08 0.05" mass="0.00745716" diaginertia="5.6949e-06 5.69477e-06 9.31377e-08" />
                        <joint name="L3-R" pos="0 0 0.1" axis="0.57735 0.57735 0.57735" type="ball"/>
                        <geom type="mesh" rgba="0.745098 0.745098 0.745098 1" mesh="L3-R" />
                        <!-- <body name="WL3-2" pos="-0.029123 -0.0072 0.05" quat="0.700126 -0.655881 -0.264239 -0.099103"> -->
                            <!-- <inertial pos="0 0 0.005" quat="0.5 0.5 -0.5 0.5" mass="0.0108253" diaginertia="2.14943e-06 1.16492e-06 1.16492e-06" /> -->
                            <!-- <joint name="WL3-2" pos="0 0 0" axis="0.57735 0.57735 0.57735" /> -->
                            <!-- <geom type="mesh" rgba="0.745098 0.745098 0.745098 1" mesh="WL3-2" /> -->
                        <!-- </body> -->
                    </body>
                </body>
            </body>
        </body>
        </body>
		
    </worldbody>
	 <actuator>
	<!-- MOTOR??? -->
        <motor name="A1" joint="A1"/>
		<motor name="A2" joint="A2"/>
		<motor name="A3" joint="A3"/>
		
    </actuator>
</mujoco>
