<mujoco model="GTPR">
	<compiler angle="radian" coordinate="local" />
	<size njmax="500" nconmax="100" />
	<!-- <option timestep="0.002" gravity="0  0 -9.81" > -->
	<option timestep="0.002" gravity="0  0 -9.81">
		<flag constraint="enable" gravity="enable">
		</flag>
	</option>
	<visual>
		<rgba haze="0.15 0.25 0.35 1" />
		<quality shadowsize="2048" />
		<map stiffness="700" shadowscale="0.5" fogstart="10" fogend="15" zfar="40" haze="0.3" />
	</visual>
	<size nconmax="300" njmax="1000" nstack="1000000" />
	<asset>
		<texture name="texplane" type="2d" builtin="checker" rgb1=".2 .3 .4" rgb2=".1 0.15 0.2" width="512" height="512" mark="cross" markrgb=".8 .8 .8" />
		<material name="matplane" reflectance="0.3" texture="texplane" texrepeat="1 1" texuniform="true" />
		<!-- bázis -->
		<mesh name="base_link" file="assets/base_link.STL" />
		<!-- felkar 1 -->
		<mesh name="A1" file="assets/A1.STL" />
		<!-- felső középrész 1 -->
		<mesh name="U1" file="assets/U1.STL" />
		<!-- bal alkar -->
		<mesh name="U1L" file="assets/U1L.STL" />
		<!-- bal alkarhoz tartozó alsórész -->
		<mesh name="L1" file="assets/L1-L.STL" />
		<!-- bal alkarhoz tartozó munkaháromszög -->
		<mesh name="WL1-1" file="assets/WL2-1.STL" />
		<!-- jobb alkar -->
		<mesh name="U1R" file="assets/U1R.STL" />
		<!-- felkar -->
		<mesh name="A2" file="assets/A2.STL" />
		<!-- felső középrész -->
		<mesh name="U2" file="assets/U2.STL" />
		<!-- bal alkar -->
		<mesh name="U2L" file="assets/U2L.STL" />
		<!-- bal alkarhoz tartozó alsórész -->
		<mesh name="L2" file="assets/L2-L.STL" />
		<!-- jobb alkar -->
		<mesh name="U2R" file="assets/U2R.STL" />
		<!-- felkar -->
		<mesh name="A3" file="assets/A3.STL" />
		<!-- felső középrész -->
		<mesh name="U3" file="assets/U3.STL" />
		<!-- bal alkar -->
		<mesh name="U3L" file="assets/U3L.STL" />
		<!-- bal alkarhoz tartozó munkaháromszög -->
		<mesh name="L3" file="assets/WL3-L.STL" />
		<mesh name="U3R" file="assets/U3R.STL" />
	</asset>
	<equality>
        <!-- <connect name="a1" anchor="0 0 0.2" active="true" body1="A1" body2="base_link">
		</connect>
        <connect name="a2" anchor="0 0 0.2" active="true" body1="A2" body2="base_link">
		</connect>
        <connect name="a3" anchor="0 0 0.2" active="true" body1="A3" body2="base_link">
		</connect> -->
		<connect name="1" anchor="0 0 0" active="true" body1="A1" body2="U1">
		</connect>
		<connect name="2" anchor="0 0 0" active="true" body1="U1" body2="U1L">
		</connect>
		<connect name="3" anchor="0 0 0.1" active="true" body1="U1" body2="U1R">
		</connect>
		<connect name="4" anchor="0 0 0" active="true" body1="U1L" body2="L1">
		</connect>
		<connect name="5" anchor="0 0 0" active="true" body1="U1R" body2="L1">
		</connect>
		<connect name="6" anchor="0 0 0" active="true" body1="A2" body2="U2">
		</connect>
		<connect name="7" anchor="0 0 0" active="true" body1="U2" body2="U2L">
		</connect>
		<connect name="8" anchor="0 0 0.1" active="true" body1="U2" body2="U2R">
		</connect>
		<connect name="9" anchor="0 0 0" active="true" body1="U2L" body2="L2">
		</connect>
		<connect name="10" anchor="0 0 0" active="true" body1="U2R" body2="L2">
		</connect>
		<connect name="11" anchor="0 0 0" active="true" body1="A3" body2="U3">
		</connect>
		<connect name="12" anchor="0 0 0" active="true" body1="U3" body2="U3L">
		</connect>
		<connect name="13" anchor="0 0 0.1" active="true" body1="U3" body2="U3R">
		</connect>
		<connect name="14" anchor="0 0 0" active="true" body1="U3L" body2="L3">
		</connect>
		<connect name="15" anchor="0 0 0" active="true" body1="U3R" body2="L3">
		</connect>
		<connect name="16" anchor="0 0 0" active="true" body1="L1" body2="WL1-1">
		</connect>
		<connect name="17" anchor="0 0 0" active="true" body1="L2" body2="WL1-1">
		</connect>
		<connect name="18" anchor="0 0 0" active="true" body1="L3" body2="WL1-1">
		</connect>
		<connect name="19" anchor="0 0 0" active="true" body1="L1" body2="L3">
		</connect>
		<connect name="20" anchor="0 0 0" active="true" body2="L1" body1="L2">
		</connect>
		<connect name="21" anchor="0 0 0" active="true" body1="L2" body2="L1">
		</connect>
		<connect name="22" anchor="0 0 0" active="true" body2="L2" body1="L3">
		</connect>
		<connect name="23" anchor="0 0 0" active="true" body1="L3" body2="L2">
		</connect>
		<connect name="24" anchor="0 0 0" active="true" body2="L3" body1="L1">
		</connect>
	</equality>
	<worldbody>
		<light directional="true" diffuse=".6 .6 .6" specular="0.2 0.2 0.2" pos="0 0 4" dir="0 0 -1" />
		<geom name="ground" type="plane" size="0 0 1" pos="0 0 0" quat="1 0 0 0" material="matplane" condim="1" />
		<body name="ball" pos="0 0 1" euler="0 0 0">
			<geom size=".015" rgba=".8 .2 .1 1" mass="0.001" />
			<joint name="fjoint" pos="0 0 0" axis="1 0 0" type="free" />
		</body>
		<body name="base_link" pos="0 0 0.005" euler="1.570807 0 0">
			<geom type="mesh" rgba="0.7451 0.7451 0.7451 1" mesh="base_link" />
			<body name="A1" pos="0 0.2 -0.15" quat="0.707105 0.707108 0 0">
				<inertial pos="5.3777e-05 4.4185e-09 0.1" mass="0.015311" diaginertia="4.8682e-05 4.8682e-05 1.9135e-07" />
				<geom type="mesh" rgba="0.7451 0.7451 0.7451 1" mesh="A1" />
				<joint name="A1" pos="0 0 0.2" axis="-40 0 0" type="hinge" limited="true" range="-100 100" damping="1.01" stiffness="0.1" />
				<body name="U1" pos="-0.05 0 0" quat="0.435887 0.556777 0.435891 0.556777">
					<inertial pos="-0.000110499 -1.29114e-08 0.05" mass="0.00745719" diaginertia="5.6949e-06 5.69478e-06 9.31377e-08" />
					<geom type="mesh" rgba="0.745098 0.745098 0.745098 1" mesh="U1" />
					<joint name="A1U1" pos="0 0 0.05" axis="0 0 1" type="hinge" range="-2.2854 1.714602" damping="0.001" />
					<joint name="U1-U1L-J" pos="0 0 0" axis="-1 0 0" type="hinge" range="-2.2854 1.714602" damping="0.001" />
					<joint name="U1-U1R-J" pos="0 0 0.1" axis="-1 0 0" type="hinge" range="-2.2854 1.714602" damping="0.001" />
					<body name="U1L" pos="0 -0.5 0" quat="-2.59734e-06 -2.59735e-06 0.707108 0.707105">
						<geom type="mesh" rgba="0.745098 0.745098 0.745098 1" mesh="U1L" />
						<inertial pos="-2.12633e-05 -2.09104e-08 0.25" mass="0.0388723" diaginertia="0.000794044 0.000794044 4.85892e-07" />
						<joint name="U1L-L1-J" pos="0 0 0" axis="-1 0 0" type="hinge" range="-2.2854 1.714602" damping="0.001" />
						<joint name="U1L-U1-J" pos="0 0 0.5" axis="-1 0 0" type="hinge" range="-2.2854 1.714602" damping="0.001" />
					</body>
					<body name="U1R" pos="0 -0.5 0.1" quat="-2.59734e-06 -2.59735e-06 0.707108 0.707105">
						<inertial pos="-2.12633e-05 -2.09104e-08 0.25" mass="0.0388723" diaginertia="0.000794044 0.000794044 4.85892e-07" />
						<geom type="mesh" rgba="0.745098 0.745098 0.745098 1" mesh="U1R" />
						<joint name="U1R-L1-J" pos="0 0 0" axis="-1 0 0" type="hinge" range="-2.2854 1.714602" damping="0.001" />
						<joint name="U1R-U1-J" pos="0 0 0.5" axis="-1 0 0" type="hinge" range="-2.2854 1.714602" damping="0.001" />
						<body name="L1" pos="0 0 0" euler="1.570807 0 3.14159">
							<geom type="mesh" rgba="0.7451 0.7451 0.7451 1" mesh="L1" />
							<inertial pos="-0.0001105 -1.2911e-08 0.05" mass="0.0074572" diaginertia="5.6949e-06 5.6948e-06 9.3138e-08" />
							<joint name="L1-U1L-J" pos="0 0 0 " axis="-1 0 0" type="hinge" />
							<joint name="L1-U1R-J" pos="0 0 0.1 " axis="-1 0 0" type="hinge" />
						</body>
					</body>
				</body>
			</body>
			<body name="A2" pos="-0.1299 0.2 0.075" quat="0.353553 0.353556 0.612372 -0.612372">
				<inertial pos="5.3777e-05 4.4185e-09 0.1" mass="0.015311" diaginertia="4.8682e-05 4.8682e-05 1.9135e-07" />
				<geom type="mesh" rgba="0.7451 0.7451 0.7451 1" mesh="A2" />
				<joint name="A2" pos="0 0 0.2" axis="-40 0 0" type="hinge" limited="true" range="-100 100" damping="1.01" stiffness="0.1" />
				<body name="U2" pos="-0.05 0 0" quat="0.435887 0.556777 0.435891 0.556777">
					<inertial pos="-0.000110499 -1.29114e-08 0.05" mass="0.00745719" diaginertia="5.6949e-06 5.69478e-06 9.31377e-08" />
					<geom type="mesh" rgba="0.745098 0.745098 0.745098 1" mesh="U2" />
					<joint name="A2U2" pos="0 0 0.05" axis="0 0 1" type="hinge" range="-2.2854 1.714602" damping="0.001" />
					<joint name="U2-U2L-J" pos="0 0 0" axis="-1 0 0" type="hinge" range="-2.2854 1.714602" damping="0.001" />
					<joint name="U2-U2R-J" pos="0 0 0.1" axis="-1 0 0" type="hinge" range="-2.2854 1.714602" damping="0.001" />
					<body name="U2L" pos="0 -0.5 0" quat="-2.59734e-06 -2.59735e-06 0.707108 0.707105">
						<geom type="mesh" rgba="0.745098 0.745098 0.745098 1" mesh="U2L" />
						<inertial pos="-2.12633e-05 -2.09104e-08 0.25" mass="0.0388723" diaginertia="0.000794044 0.000794044 4.85892e-07" />
						<joint name="U2L-L2-J" pos="0 0 0" axis="-1 0 0" type="hinge" range="-2.2854 1.714602" damping="0.001" />
						<joint name="U2L-U2-J" pos="0 0 0.5" axis="-1 0 0" type="hinge" range="-2.2854 1.714602" damping="0.001" />
					</body>
					<body name="U2R" pos="0 -0.5 0.1" quat="-2.59734e-06 -2.59735e-06 0.707108 0.707105">
						<inertial pos="-2.12633e-05 -2.09104e-08 0.25" mass="0.0388723" diaginertia="0.000794044 0.000794044 4.85892e-07" />
						<geom type="mesh" rgba="0.745098 0.745098 0.745098 1" mesh="U2R" />
						<joint name="U2R-L2-J" pos="0 0 0" axis="-1 0 0" type="hinge" range="-2.2854 1.714602" damping="0.001" />
						<joint name="U2R-U2-J" pos="0 0 0.5" axis="-1 0 0" type="hinge" range="-2.2854 1.714602" damping="0.001" />
						<body name="L2" pos="0 0 0" euler="1.570807 0 3.14159">
							<inertial pos="-0.0001105 -1.2911e-08 0.05" mass="0.0074572" diaginertia="5.6949e-06 5.6948e-06 9.3138e-08" />
							<joint name="L2-U2L-J" pos="0 0 0 " axis="-1 0 0" type="hinge" />
							<joint name="L2-U2R-J" pos="0 0 0.1 " axis="-1 0 0" type="hinge" />
							<joint name="L2-WL1-J" pos="0 0 0.05 " axis="0 0 -0.5" type="hinge" />
							<geom type="mesh" rgba="0.7451 0.7451 0.7451 1" mesh="L2" />
						</body>
					</body>
				</body>
			</body>
			<body name="A3" pos="0.1299 0.2 0.075" quat="0.353553 0.353556 -0.612372 0.612372">
				<inertial pos="5.3777e-05 4.4185e-09 0.1" mass="0.015311" diaginertia="4.8682e-05 4.8682e-05 1.9135e-07" />
				<geom type="mesh" rgba="0.7451 0.7451 0.7451 1" mesh="A3" />
				<joint name="A3" pos="0 0 0.2" axis="-40 0 0" type="hinge" limited="true" range="-100 100" damping="1.01" stiffness="0.1" />
				<body name="U3" pos="-0.05 0 0" quat="0.435887 0.556777 0.435891 0.556777">
					<inertial pos="-0.000110499 -1.29114e-08 0.05" mass="0.00745719" diaginertia="5.6949e-06 5.69478e-06 9.31377e-08" />
					<geom type="mesh" rgba="0.745098 0.745098 0.745098 1" mesh="U3" />
					<joint name="A3U3" pos="0 0 0.05" axis="0 0 1" type="hinge" range="-2.2854 1.714602" damping="0.001" />
					<joint name="U3-U3L-J" pos="0 0 0" axis="-1 0 0" type="hinge" range="-2.2854 1.714602" damping="0.001" />
					<joint name="U3-U3R-J" pos="0 0 0.1" axis="-1 0 0" type="hinge" range="-2.2854 1.714602" damping="0.001" />
					<body name="U3L" pos="0 -0.5 0" quat="-2.59734e-06 -2.59735e-06 0.707108 0.707105">
						<geom type="mesh" rgba="0.745098 0.745098 0.745098 1" mesh="U3L" />
						<inertial pos="-2.12633e-05 -2.09104e-08 0.25" mass="0.0388723" diaginertia="0.000794044 0.000794044 4.85892e-07" />
						<joint name="U3L-L3-J" pos="0 0 0" axis="-1 0 0" type="hinge" range="-2.2854 1.714602" damping="0.001" />
						<joint name="U3L-U3-J" pos="0 0 0.5" axis="-1 0 0" type="hinge" range="-2.2854 1.714602" damping="0.001" />
					</body>
					<body name="U3R" pos="0 -0.5 0.1" quat="-2.59734e-06 -2.59735e-06 0.707108 0.707105">
						<inertial pos="-2.12633e-05 -2.09104e-08 0.25" mass="0.0388723" diaginertia="0.000794044 0.000794044 4.85892e-07" />
						<geom type="mesh" rgba="0.745098 0.745098 0.745098 1" mesh="U3R" />
						<joint name="U3R-L3-J" pos="0 0 0" axis="-1 0 0" type="hinge" range="-2.2854 1.714602" damping="0.001" />
						<joint name="U3R-U3-J" pos="0 0 0.5" axis="-1 0 0" type="hinge" range="-2.2854 1.714602" damping="0.001" />
						<body name="L3" pos="0 0 0" euler="1.570807 0 3.14159">
							<inertial pos="-0.0001105 -1.2911e-08 0.05" mass="0.0074572" diaginertia="5.6949e-06 5.6948e-06 9.3138e-08" />
							<joint name="L3-U3L-J" pos="0 0 0 " axis="-1 0 0" type="hinge" />
							<joint name="L3-U3R-J" pos="0 0 0.1 " axis="-1 0 0" type="hinge" />
							<joint name="L3-WL1-J" pos="0 0 0.05 " axis="0 0 -0.5" type="hinge" />
							<geom type="mesh" rgba="0.7451 0.7451 0.7451 1" mesh="L3" />
						</body>
					</body>
				</body>
			</body>
		</body>
		<body name="WL1-1" pos="0 0 0.7" euler="0 0 0 ">
			<inertial pos="0 0 0.005" quat="0.5 0.5 -0.5 0.5" mass="0.010825" diaginertia="2.1494e-06 1.1649e-06 1.1649e-06" />
			<geom type="mesh" rgba="0.7451 0.7451 0.7451 1" mesh="WL1-1" />
			<joint name="WL1-L2-J" pos="0 -0.03 0" axis="-0.3 0 0" type="free" />
			<body name="platform" pos="0 0 0.018" euler="0  0 0">
				<geom type="cylinder" rgba="0.7451 0.7451 0.7451 1" mass="0.000001" size="0.1 .0028 100" />
			</body>
		</body>
	</worldbody>
	<actuator>
		<position name="A1" joint="A1" />
		<position name="A2" joint="A2" />
		<position name="A3" joint="A3" />
	</actuator>
</mujoco>
