<mujoco model="GTPR">
    <compiler angle="radian" />
    <size njmax="500" nconmax="100" />
	<option gravity="0 9.81 0"/>
    <asset>
        <mesh name="base_link" file="base_link.STL" />
        <mesh name="A1" file="A1.STL" />
    </asset>
    <worldbody>
	    <body name="base_link" pos="-2.3525E-17 -0.005 2.3559E-17" >
        <geom type="mesh" rgba="0.7451 0.7451 0.7451 1" mesh="base_link" />
            <body name="A1" pos="0 0.2 -0.15" quat="0.707105 0.707108 0 0">
            <inertial pos="5.3777e-05 4.4185e-09 0.1" mass="0.015311" diaginertia="4.8682e-05 4.8682e-05 1.9135e-07" />
            <joint name="A1" pos="0 0 0.2" axis="-40 0 0" type="hinge" range="-2.2854 1.714602" damping="0.01"/>
            <geom type="mesh" rgba="0.7451 0.7451 0.7451 1" mesh="A1" />
            </body>
        </body>
    </worldbody>
	 <actuator>
        <motor name="A1" joint="A1"/>
    </actuator>
</mujoco>